Traceback (most recent call last):
  File "/Users/humphreyyang/anaconda3/envs/quantecon/lib/python3.9/site-packages/jupyter_cache/executors/utils.py", line 58, in single_nb_execution
    executenb(
  File "/Users/humphreyyang/anaconda3/envs/quantecon/lib/python3.9/site-packages/nbclient/client.py", line 1204, in execute
    return NotebookClient(nb=nb, resources=resources, km=km, **kwargs).execute()
  File "/Users/humphreyyang/anaconda3/envs/quantecon/lib/python3.9/site-packages/nbclient/util.py", line 84, in wrapped
    return just_run(coro(*args, **kwargs))
  File "/Users/humphreyyang/anaconda3/envs/quantecon/lib/python3.9/site-packages/nbclient/util.py", line 62, in just_run
    return loop.run_until_complete(coro)
  File "/Users/humphreyyang/anaconda3/envs/quantecon/lib/python3.9/asyncio/base_events.py", line 647, in run_until_complete
    return future.result()
  File "/Users/humphreyyang/anaconda3/envs/quantecon/lib/python3.9/site-packages/nbclient/client.py", line 663, in async_execute
    await self.async_execute_cell(
  File "/Users/humphreyyang/anaconda3/envs/quantecon/lib/python3.9/site-packages/nbclient/client.py", line 965, in async_execute_cell
    await self._check_raise_for_error(cell, cell_index, exec_reply)
  File "/Users/humphreyyang/anaconda3/envs/quantecon/lib/python3.9/site-packages/nbclient/client.py", line 862, in _check_raise_for_error
    raise CellExecutionError.from_cell_and_msg(cell, exec_reply_content)
nbclient.exceptions.CellExecutionError: An error occurred while executing the following cell:
------------------
e(p, A, b, c)
------------------

[0;31m---------------------------------------------------------------------------[0m
[0;31mValueError[0m                                Traceback (most recent call last)
Cell [0;32mIn[52], line 1[0m
[0;32m----> 1[0m [43me[49m[43m([49m[43mp[49m[43m,[49m[43m [49m[43mA[49m[43m,[49m[43m [49m[43mb[49m[43m,[49m[43m [49m[43mc[49m[43m)[49m

Cell [0;32mIn[35], line 2[0m, in [0;36me[0;34m(p, A, b, c)[0m
[1;32m      1[0m [38;5;28;01mdef[39;00m [38;5;21me[39m(p, A, b, c):
[0;32m----> 2[0m     [38;5;28;01mreturn[39;00m np[38;5;241m.[39mexp([38;5;241m-[39m [43mnp[49m[38;5;241;43m.[39;49m[43mdot[49m[43m([49m[43mA[49m[43m,[49m[43m [49m[43mp[49m[43m)[49m) [38;5;241m+[39m c [38;5;241m-[39m b [38;5;241m*[39m np[38;5;241m.[39msqrt(p)

File [0;32m~/anaconda3/envs/quantecon/lib/python3.9/site-packages/autograd/tracer.py:48[0m, in [0;36mprimitive.<locals>.f_wrapped[0;34m(*args, **kwargs)[0m
[1;32m     46[0m     [38;5;28;01mreturn[39;00m new_box(ans, trace, node)
[1;32m     47[0m [38;5;28;01melse[39;00m:
[0;32m---> 48[0m     [38;5;28;01mreturn[39;00m [43mf_raw[49m[43m([49m[38;5;241;43m*[39;49m[43margs[49m[43m,[49m[43m [49m[38;5;241;43m*[39;49m[38;5;241;43m*[39;49m[43mkwargs[49m[43m)[49m

File [0;32m<__array_function__ internals>:5[0m, in [0;36mdot[0;34m(*args, **kwargs)[0m

[0;31mValueError[0m: shapes (3,3) and (3000,) not aligned: 3 (dim 1) != 3000 (dim 0)
ValueError: shapes (3,3) and (3000,) not aligned: 3 (dim 1) != 3000 (dim 0)

